<mujoco model="MuJoCo Model">
  <!--Compiler Options-->
  <compiler angle="radian"/>
  <option timestep="0.001" gravity="0 0 -9.81" density="1.225" viscosity="1.8e-05" integrator="RK4" jacobian="sparse">
    <flag energy="enable" contact="enable"/>
  </option>

  <visual>
    <headlight diffuse="0.6 0.6 0.6" ambient="0.3 0.3 0.3" specular="0 0 0"/>
    <rgba haze="0.15 0.25 0.35 1"/>
    <global azimuth="-20" elevation="-20" ellipsoidinertia="true"/>
  </visual>  

  <asset>
    <texture type="skybox" builtin="gradient" rgb1="0.3 0.5 0.7" rgb2="0 0 0" width="512" height="3072"/>
    <texture type="2d" name="groundplane" builtin="checker" mark="edge" rgb1="0.2 0.3 0.4" rgb2="0.1 0.2 0.3"
      markrgb="0.8 0.8 0.8" width="300" height="300"/>
    <material name="groundplane" texture="groundplane" texuniform="true" texrepeat="5 5" reflectance="0.2"/>
  </asset>

  <default>
        <site type="sphere" rgba="1 0 0 1" size="0.005"/>
        <tendon limited="true" width="0.003" rgba="1 1 1 1"/>
        <geom friction=".2"/>
  </default>

  <worldbody>
    <light pos="0 0 1.5" dir="0 0 -1" directional="true"/>
    <geom name="floor" size="0 0 0.05" type="plane" material="groundplane"/>

    <camera name="Upper_view" pos="0.0 0.0 6.0" quat="1 0.0 0.0 0.0" mode="trackcom"/>
    <camera name="Track_view" pos="0 -1 .5" quat="0.707 0.70 0.0 0.0" mode="trackcom"/>

    <!-- System Models -->
    <!-- Block fized postion, free rotation -->
    <body name="block_1" pos="0 0 1">
      <joint pos="0 0 0" type="ball" actuatorfrclimited="false" damping="1"/>
      <geom size="0.1 0.2 0.3" type="box" rgba="0 0.9 0 1"/>
    </body>

    <!-- Free body only in xyz axis -->
    <body name="floating_box" pos="0 1 3">
        <joint name="joint_x" pos="0 0 0" type="slide" axis="1 0 0" limited="true" range="-3 3" damping="100"/>
        <joint name="joint_y" pos="0 0 0" type="slide" axis="0 1 0" limited="true" range="-3 3" damping="100"/>
        <joint name="joint_z" pos="0 0 0" type="slide" axis="0 0 1" limited="true" range="-0.5 0.5" damping="100"/>
      <geom size="0.2" type="sphere" rgba="1 0 0 1"/>
      <site name="origin0" pos="0 0 0"/>
    </body>

    <!-- Free body -->
    <body name="box_3" pos="0 1 1">
      <joint name="free_joint" pos="0 0 0" type="free" damping="1"/>
      <geom size="0.1 0.1 0.1" type="box" rgba="0 0 1 1"/>
      <site name="insertion0" pos="0.1 0.1 0.1"/>
      <site name="insertion1" pos="-0.1 0.1 0.1"/>
      <site name="insertion2" pos="-0.1 -0.1 0.1"/>
      <site name="insertion3" pos="0.1 -0.1 0.1"/>
    </body>
  </worldbody>

    <tendon>
        <spatial name="rope0" range="0 2">
            <site site="origin0"/>
            <site site="insertion0"/>
        </spatial>
    </tendon>

    <tendon>
        <spatial name="rope1" range="0 2">
            <site site="origin0"/>
            <site site="insertion1"/>
        </spatial>
    </tendon>

    <tendon>
        <spatial name="rope2" range="0 2">
            <site site="origin0"/>
            <site site="insertion2"/>
        </spatial>
    </tendon>

    <tendon>
        <spatial name="rope3" range="0 2">
            <site site="origin0"/>
            <site site="insertion3"/>
        </spatial>
    </tendon>
</mujoco>
