<mujoco model="MuJoCo Model">
  <!--Compiler Options-->
  <compiler angle="radian"/>
  <option timestep="0.001" gravity="0 0 -9.81" density="1.225" viscosity="1.8e-05" integrator="RK4" jacobian="sparse">
    <flag energy="enable"/>
  </option>
  <asset>
    <texture type="2d" name="grid" builtin="checker" rgb1="0.5 0.5 0.3" rgb2="0.2 0.3 0.4" width="300" height="300"/>
    <material name="grid" texture="grid" texrepeat="8 8" reflectance="0.2"/>
  </asset>

  <default>
        <site type="sphere" rgba="1 0 0 1" size="0.005"/>
        <tendon limited="true" width="0.003" rgba="1 1 1 1"/>
        <geom friction=".2"/>
    </default>

  <worldbody>
    <geom size="15 15 0.1" type="plane" material="grid"/>
    <camera pos="-0.225 -3.653 6.399" quat="0.952859 0.302614 0.00666095 0.0209737"/>
    <light pos="0 0 20" dir="0 0 -1" diffuse="1 1 1"/>
    <body name="block_1" pos="0 0 1">
      <joint pos="0 0 0" type="ball" actuatorfrclimited="false" damping="1"/>
      <geom size="0.1 0.2 0.3" type="box" rgba="0 0.9 0 1"/>
    </body>
    <body name="floating_box" pos="0 1 3">
        <joint name="joint_x" pos="0 0 0" type="slide" axis="1 0 0" limited="true" range="-3 3" damping="100"/>
        <joint name="joint_y" pos="0 0 0" type="slide" axis="0 1 0" limited="true" range="-3 3" damping="100"/>
        <joint name="joint_z" pos="0 0 0" type="slide" axis="0 0 1" limited="true" range="-1 1" damping="100"/>
      <geom size="0.2" type="sphere" rgba="1 0 0 1"/>
      <site name="origin0" pos="0 0 0"/>
    </body>

    <body name="box_3" pos="0 1 1">
      <joint name="free_joint" pos="0 0 0" type="free" damping="1"/>
      <geom size="0.1 0.1 0.1" type="box" rgba="0 0 1 1"/>
      <site name="insertion0" pos="0.1 0.1 0.1"/>
      <site name="insertion1" pos="-0.1 0.1 0.1"/>
      <site name="insertion2" pos="-0.1 -0.1 0.1"/>
      <site name="insertion3" pos="0.1 -0.1 0.1"/>
    </body>
  </worldbody>

    <tendon>
        <spatial name="rope0" range="0 2">
            <site site="origin0"/>
            <site site="insertion0"/>
        </spatial>
    </tendon>
    <tendon>
        <spatial name="rope1" range="0 2">
            <site site="origin0"/>
            <site site="insertion1"/>
        </spatial>
    </tendon>
    <tendon>
        <spatial name="rope2" range="0 2">
            <site site="origin0"/>
            <site site="insertion2"/>
        </spatial>
    </tendon>
    <tendon>
        <spatial name="rope3" range="0 2">
            <site site="origin0"/>
            <site site="insertion3"/>
        </spatial>
    </tendon>
</mujoco>
